<testsuite errors="1" failures="3" name="FilterTutor.Filter Tutors" skipped="0" tests="4" time="2.470329"><testcase classname="FilterTutor.Filter Tutors" name="Mike wants to filter tutors by subject" status="failed" time="0.968979"><error message="&quot;&lt;Tutor: user-0&gt;&quot; needs to have a value for field &quot;tutor&quot; before this many-to-ma..." type="ValueError">
<![CDATA[
Failing step: When Mike enters "BCS421" ... failed in 0.129s
Location: features/FilterTutor.feature:13
Traceback (most recent call last):
  File "/usr/local/lib/python3.5/site-packages/django/db/models/query.py", line 473, in get_or_create
    return self.get(**lookup), False
  File "/usr/local/lib/python3.5/site-packages/django/db/models/query.py", line 385, in get
    self.model._meta.object_name
nectr.tutor.models.DoesNotExist: Tutor matching query does not exist.

During handling of the above exception, another exception occurred:

Traceback (most recent call last):
  File "/usr/local/lib/python3.5/site-packages/behave/model.py", line 1456, in run
    match.run(runner.context)
  File "/usr/local/lib/python3.5/site-packages/behave/model.py", line 1903, in run
    self.func(context, *args, **kwargs)
  File "features/steps/FilterTutor.py", line 91, in step_impl
    tutor = TutorFactory(courses=course_name)
  File "/usr/local/lib/python3.5/site-packages/factory/base.py", line 69, in __call__
    return cls.create(**kwargs)
  File "/usr/local/lib/python3.5/site-packages/factory/base.py", line 623, in create
    return cls._generate(True, attrs)
  File "/usr/local/lib/python3.5/site-packages/factory/base.py", line 548, in _generate
    obj = cls._prepare(create, **attrs)
  File "/usr/local/lib/python3.5/site-packages/factory/base.py", line 523, in _prepare
    return cls._create(model_class, *args, **kwargs)
  File "/usr/local/lib/python3.5/site-packages/factory/django.py", line 179, in _create
    return cls._get_or_create(model_class, *args, **kwargs)
  File "/usr/local/lib/python3.5/site-packages/factory/django.py", line 170, in _get_or_create
    obj, _created = manager.get_or_create(*args, **key_fields)
  File "/usr/local/lib/python3.5/site-packages/django/db/models/manager.py", line 85, in manager_method
    return getattr(self.get_queryset(), name)(*args, **kwargs)
  File "/usr/local/lib/python3.5/site-packages/django/db/models/query.py", line 475, in get_or_create
    return self._create_object_from_params(lookup, params)
  File "/usr/local/lib/python3.5/site-packages/django/db/models/query.py", line 505, in _create_object_from_params
    obj = self.create(**params)
  File "/usr/local/lib/python3.5/site-packages/django/db/models/query.py", line 397, in create
    obj = self.model(**kwargs)
  File "/usr/local/lib/python3.5/site-packages/django/db/models/base.py", line 550, in __init__
    setattr(self, prop, kwargs[prop])
  File "/usr/local/lib/python3.5/site-packages/django/db/models/fields/related_descriptors.py", line 499, in __set__
    manager = self.__get__(instance)
  File "/usr/local/lib/python3.5/site-packages/django/db/models/fields/related_descriptors.py", line 476, in __get__
    return self.related_manager_cls(instance)
  File "/usr/local/lib/python3.5/site-packages/django/db/models/fields/related_descriptors.py", line 783, in __init__
    (instance, self.source_field_name))
ValueError: "<Tutor: user-0>" needs to have a value for field "tutor" before this many-to-many relationship can be used.
]]>
</error><system-out>
<![CDATA[
@scenario.begin
  Scenario: Mike wants to filter tutors by subject
    Given Mike is on nectr web site ... passed in 0.599s
    Given Mike is on Search the hive page ... passed in 0.241s
    When Mike enters "BCS421" ... failed in 0.129s
    Then all tutors who tutor that subject will be displayed ... skipped in 0.000s

@scenario.end
--------------------------------------------------------------------------------
]]>
</system-out></testcase><testcase classname="FilterTutor.Filter Tutors" name="Mike wants to filter tutors by subject" status="failed" time="0.537832"><failure message="" type="AssertionError">
<![CDATA[
Failing step: And Mike has not yet selected a tutor ... failed in 0.000s
Location: features/FilterTutor.feature:18
Traceback (most recent call last):
  File "/usr/local/lib/python3.5/site-packages/behave/model.py", line 1456, in run
    match.run(runner.context)
  File "/usr/local/lib/python3.5/site-packages/behave/model.py", line 1903, in run
    self.func(context, *args, **kwargs)
  File "features/steps/FilterTutor.py", line 15, in step_impl
    assert False
AssertionError
]]>
</failure><system-out>
<![CDATA[
@scenario.begin
  Scenario: Mike wants to filter tutors by subject
    Given Mike is on nectr web site ... passed in 0.315s
    Given Mike is on Search the hive page ... passed in 0.223s
    And Mike has not yet selected a tutor ... failed in 0.000s
    When Mike clicks <subject> radio button on subject filter ... skipped in 0.000s
    Then all tutors who tutor <subject> will be displayed ... skipped in 0.000s

@scenario.end
--------------------------------------------------------------------------------
]]>
</system-out></testcase><testcase classname="FilterTutor.Filter Tutors" name="Mike wants to filter tutors by availability" status="failed" time="0.483606"><failure message="" type="AssertionError">
<![CDATA[
Failing step: And Mike has not yet selected a tutor ... failed in 0.000s
Location: features/FilterTutor.feature:24
Traceback (most recent call last):
  File "/usr/local/lib/python3.5/site-packages/behave/model.py", line 1456, in run
    match.run(runner.context)
  File "/usr/local/lib/python3.5/site-packages/behave/model.py", line 1903, in run
    self.func(context, *args, **kwargs)
  File "features/steps/FilterTutor.py", line 15, in step_impl
    assert False
AssertionError
]]>
</failure><system-out>
<![CDATA[
@scenario.begin
  Scenario: Mike wants to filter tutors by availability
    Given Mike is on nectr web site ... passed in 0.263s
    Given Mike is on Search the hive page ... passed in 0.220s
    And Mike has not yet selected a tutor ... failed in 0.000s
    When Mike clicks <dayOfTheWeek> radio button on availability filter ... skipped in 0.000s
    Then all tutors who tutor on that day will be displayed ... skipped in 0.000s

@scenario.end
--------------------------------------------------------------------------------
]]>
</system-out></testcase><testcase classname="FilterTutor.Filter Tutors" name="Mike wants to filter tutors by price" status="failed" time="0.479912"><failure message="" type="AssertionError">
<![CDATA[
Failing step: And Mike has not yet selected a tutor ... failed in 0.000s
Location: features/FilterTutor.feature:30
Traceback (most recent call last):
  File "/usr/local/lib/python3.5/site-packages/behave/model.py", line 1456, in run
    match.run(runner.context)
  File "/usr/local/lib/python3.5/site-packages/behave/model.py", line 1903, in run
    self.func(context, *args, **kwargs)
  File "features/steps/FilterTutor.py", line 15, in step_impl
    assert False
AssertionError
]]>
</failure><system-out>
<![CDATA[
@scenario.begin
  Scenario: Mike wants to filter tutors by price
    Given Mike is on nectr web site ... passed in 0.254s
    Given Mike is on Search the hive page ... passed in 0.225s
    And Mike has not yet selected a tutor ... failed in 0.000s
    When Mike wants to filter by hourly rate ... skipped in 0.000s
    Then Mike should be able to filter using a slider ... skipped in 0.000s

@scenario.end
--------------------------------------------------------------------------------
]]>
</system-out></testcase></testsuite>